<?xml version="1.0" ?>
<!-- =================================================================================== -->
<!-- |    This document was autogenerated by xacro from /home/ljx/workspace/rm_robot_ws/src/rm_robot/rm_description/urdf/RML63_6F/rm_63_6f_description.urdf.xacro | -->
<!-- |    EDITING THIS FILE BY HAND IS NOT RECOMMENDED                                 | -->
<!-- =================================================================================== -->
<!-- This URDF was automatically created by SolidWorks to URDF Exporter! Originally created by Stephen Brawner (brawner@gmail.com) 
     Commit Version: 1.6.0-1-g15f4949  Build Version: 1.6.7594.29634
     For more information, please see http://wiki.ros.org/sw_urdf_exporter -->
<robot name="rm_63_6f_description">
    <link name="world" />
    <!-- ///////////////////////////////////////   bottom_joint   ////////////////////////////////////////// -->
    <joint name="bottom_joint" type="fixed">
        <origin rpy="0 0 0" xyz="0 0 0" />
        <parent link="base_link" />
        <child link="bottom_link" />
    </joint>
    <link name="bottom_link">
        <visual>
            <origin rpy="0 0 0" xyz=" 0 0 -0.02" />
            <geometry>
                <box size="0.06 0.06 0.02" />
            </geometry>
            <material name="Brown" />
        </visual>
        <collision>
            <origin rpy="0 0 0" xyz=" 0 0 0" />
            <geometry>
                <box size="0.06 0.06 0.02" />
            </geometry>
        </collision>
        <inertial>
            <mass value="500" />
            <inertia ixx="41.68333333333333" ixy="0" ixz="0" iyy="83.33333333333333" iyz="0" izz="41.68333333333333" />
            <origin xyz="0 0 0" rpy="0 0 0" />
        </inertial>
    </link>
    <link name="base_link">
        <inertial>
            <origin rpy="0 0 0" xyz="0.001418 -0.00010076 0.050086" />
            <mass value="0.66248" />
            <inertia ixx="0.00099641" ixy="3.2555E-06" ixz="-1.005E-05" iyy="0.0010163" iyz="1.2819E-06" izz="0.00067925" />
        </inertial>
        <visual>
            <origin rpy="0 0 0" xyz="0 0 0" />
            <geometry>
                <mesh filename="package://rm_description/meshes/RML63_6F/base_link.STL" />
            </geometry>
            <material name="">
                <color rgba="1 1 1 1" />
            </material>
        </visual>
        <collision>
            <origin rpy="0 0 0" xyz="0 0 0" />
            <geometry>
                <mesh filename="package://rm_description/meshes/RML63_6F/base_link.STL" />
            </geometry>
        </collision>
    </link>
    <gazebo reference="base_link">
        <mu1 value="200000.0" />
        <mu2 value="200000.0" />
        <kp value="100000000.0" />
        <kd value="1.0" />
        <plugin name="gazebo_ros_control" filename="libgazebo_ros_control.so">
            <robotNamespace>/</robotNamespace>
        </plugin>
    </gazebo>
    <joint name="world_to_base" type="fixed">
        <parent link="world" />
        <child link="base_link" />
        <origin rpy="0 0 0" xyz="0 0 0.85" />
    </joint>
    <link name="Link1">
        <inertial>
            <origin rpy="0 0 0" xyz="-0.043398 -0.0074204 -0.012727" />
            <mass value="0.92308" />
            <inertia ixx="0.00093348" ixy="-0.00032512" ixz="0.00049759" iyy="0.0021248" iyz="0.00010864" izz="0.001984" />
        </inertial>
        <visual>
            <origin rpy="0 0 0" xyz="0 0 0" />
            <geometry>
                <mesh filename="package://rm_description/meshes/RML63_6F/Link1.STL" />
            </geometry>
            <material name="">
                <color rgba="1 1 1 1" />
            </material>
        </visual>
        <collision>
            <origin rpy="0 0 0" xyz="0 0 0" />
            <geometry>
                <mesh filename="package://rm_description/meshes/RML63_6F/Link1.STL" />
            </geometry>
        </collision>
    </link>
    <joint name="joint1" type="revolute">
        <origin rpy="0 0 0" xyz="0 0 0.172" />
        <parent link="base_link" />
        <child link="Link1" />
        <axis xyz="0 0 1" />
        <limit effort="100" lower="-3.107" upper="3.107" velocity="1" />
    </joint>
    <link name="Link2">
        <inertial>
            <origin rpy="0 0 0" xyz="0.17251 -1.2589E-07 -0.090386" />
            <mass value="1.5577" />
            <inertia ixx="0.0009796" ixy="-1.2068E-07" ixz="-2.8708E-05" iyy="0.026357" iyz="1.3036E-09" izz="0.026573" />
        </inertial>
        <visual>
            <origin rpy="0 0 0" xyz="0 0 0" />
            <geometry>
                <mesh filename="package://rm_description/meshes/RML63_6F/Link2.STL" />
            </geometry>
            <material name="">
                <color rgba="1 1 1 1" />
            </material>
        </visual>
        <collision>
            <origin rpy="0 0 0" xyz="0 0 0" />
            <geometry>
                <mesh filename="package://rm_description/meshes/RML63_6F/Link2.STL" />
            </geometry>
        </collision>
    </link>
    <joint name="joint2" type="revolute">
        <origin rpy="-1.5708 -1.5708 0" xyz="-0.086 0 0" />
        <parent link="Link1" />
        <child link="Link2" />
        <axis xyz="0 0 1" />
        <limit effort="100" lower="-3.107" upper="3.107" velocity="1" />
    </joint>
    <link name="Link3">
        <inertial>
            <origin rpy="0 0 0" xyz="0.036479 -0.021595 -0.0052425" />
            <mass value="0.71556" />
            <inertia ixx="0.00081897" ixy="0.0004323" ixz="-0.00015721" iyy="0.0011167" iyz="9.5746E-05" izz="0.0013828" />
        </inertial>
        <visual>
            <origin rpy="0 0 0" xyz="0 0 0" />
            <geometry>
                <mesh filename="package://rm_description/meshes/RML63_6F/Link3.STL" />
            </geometry>
            <material name="">
                <color rgba="1 1 1 1" />
            </material>
        </visual>
        <collision>
            <origin rpy="0 0 0" xyz="0 0 0" />
            <geometry>
                <mesh filename="package://rm_description/meshes/RML63_6F/Link3.STL" />
            </geometry>
        </collision>
    </link>
    <joint name="joint3" type="revolute">
        <origin rpy="0 0 1.5708" xyz="0.38 0 -0.00010023" />
        <parent link="Link2" />
        <child link="Link3" />
        <axis xyz="0 0 1" />
        <limit effort="100" lower="-3.107" upper="2.531" velocity="1" />
    </joint>
    <link name="Link4">
        <inertial>
            <origin rpy="0 0 0" xyz="-5.2717E-06 -0.033557 -0.18296" />
            <mass value="0.69692" />
            <inertia ixx="0.0071528" ixy="-6.0923E-09" ixz="8.8515E-08" iyy="0.006708" iyz="0.0016525" izz="0.00074662" />
        </inertial>
        <visual>
            <origin rpy="0 0 0" xyz="0 0 0" />
            <geometry>
                <mesh filename="package://rm_description/meshes/RML63_6F/Link4.STL" />
            </geometry>
            <material name="">
                <color rgba="1 1 1 1" />
            </material>
        </visual>
        <collision>
            <origin rpy="0 0 0" xyz="0 0 0" />
            <geometry>
                <mesh filename="package://rm_description/meshes/RML63_6F/Link4.STL" />
            </geometry>
        </collision>
    </link>
    <joint name="joint4" type="revolute">
        <origin rpy="1.5708 0 0" xyz="0.069 -0.405 9.9684E-05" />
        <parent link="Link3" />
        <child link="Link4" />
        <axis xyz="0 0 1" />
        <limit effort="100" lower="-3.107" upper="3.107" velocity="1" />
    </joint>
    <link name="Link5">
        <inertial>
            <origin rpy="0 0 0" xyz="-2.2615E-07 0.02789 -0.0066313" />
            <mass value="0.3567" />
            <inertia ixx="0.00041098" ixy="-8.4722E-09" ixz="-4.3897E-09" iyy="0.00017907" iyz="-8.7584E-05" izz="0.00038034" />
        </inertial>
        <visual>
            <origin rpy="0 0 0" xyz="0 0 0" />
            <geometry>
                <mesh filename="package://rm_description/meshes/RML63_6F/Link5.STL" />
            </geometry>
            <material name="">
                <color rgba="1 1 1 1" />
            </material>
        </visual>
        <collision>
            <origin rpy="0 0 0" xyz="0 0 0" />
            <geometry>
                <mesh filename="package://rm_description/meshes/RML63_6F/Link5.STL" />
            </geometry>
        </collision>
    </link>
    <joint name="joint5" type="revolute">
        <origin rpy="1.5708 0 3.1416" xyz="0 0 0" />
        <parent link="Link4" />
        <child link="Link5" />
        <axis xyz="0 0 1" />
        <limit effort="100" lower="-3.107" upper="3.107" velocity="1" />
    </joint>
    <link name="Link6">
        <inertial>
            <origin rpy="0 0 0" xyz="-0.00032091 0.00017748 -0.028468" />
            <mass value="0.14814" />
            <inertia ixx="7.2093E-05" ixy="-1.2989E-06" ixz="7.9524E-07" iyy="7.063E-05" iyz="-4.3017E-07" izz="6.2819E-05" />
        </inertial>
        <visual>
            <origin rpy="0 0 0" xyz="0 0 0" />
            <geometry>
                <mesh filename="package://rm_description/meshes/RML63_6F/Link6.STL" />
            </geometry>
            <material name="">
                <color rgba="1 1 1 1" />
            </material>
        </visual>
        <collision>
            <origin rpy="0 0 0" xyz="0 0 0" />
            <geometry>
                <mesh filename="package://rm_description/meshes/RML63_6F/Link6.STL" />
            </geometry>
        </collision>
    </link>
    <joint name="joint6" type="revolute">
        <origin rpy="1.5708 0 -3.1416" xyz="0 0.1435 0" />
        <parent link="Link5" />
        <child link="Link6" />
        <axis xyz="0 0 1" />
        <limit effort="100" lower="-6.283" upper="6.283" velocity="1" />
    </joint>
    <transmission name="tran1">
        <type>transmission_interface/SimpleTransmission</type>
        <joint name="joint1">
            <hardwareInterface>hardware_interface/PositionJointInterface</hardwareInterface>
        </joint>
        <actuator name="motor1">
            <hardwareInterface>hardware_interface/PositionJointInterface</hardwareInterface>
            <mechanicalReduction>1</mechanicalReduction>
        </actuator>
    </transmission>
    <transmission name="tran1">
        <type>transmission_interface/SimpleTransmission</type>
        <joint name="joint2">
            <hardwareInterface>hardware_interface/PositionJointInterface</hardwareInterface>
        </joint>
        <actuator name="motor1">
            <hardwareInterface>hardware_interface/PositionJointInterface</hardwareInterface>
            <mechanicalReduction>1</mechanicalReduction>
        </actuator>
    </transmission>
    <transmission name="tran1">
        <type>transmission_interface/SimpleTransmission</type>
        <joint name="joint3">
            <hardwareInterface>hardware_interface/PositionJointInterface</hardwareInterface>
        </joint>
        <actuator name="motor1">
            <hardwareInterface>hardware_interface/PositionJointInterface</hardwareInterface>
            <mechanicalReduction>1</mechanicalReduction>
        </actuator>
    </transmission>
    <transmission name="tran1">
        <type>transmission_interface/SimpleTransmission</type>
        <joint name="joint4">
            <hardwareInterface>hardware_interface/PositionJointInterface</hardwareInterface>
        </joint>
        <actuator name="motor1">
            <hardwareInterface>hardware_interface/PositionJointInterface</hardwareInterface>
            <mechanicalReduction>1</mechanicalReduction>
        </actuator>
    </transmission>
    <transmission name="tran1">
        <type>transmission_interface/SimpleTransmission</type>
        <joint name="joint5">
            <hardwareInterface>hardware_interface/PositionJointInterface</hardwareInterface>
        </joint>
        <actuator name="motor1">
            <hardwareInterface>hardware_interface/PositionJointInterface</hardwareInterface>
            <mechanicalReduction>1</mechanicalReduction>
        </actuator>
    </transmission>
    <transmission name="tran1">
        <type>transmission_interface/SimpleTransmission</type>
        <joint name="joint6">
            <hardwareInterface>hardware_interface/PositionJointInterface</hardwareInterface>
        </joint>
        <actuator name="motor1">
            <hardwareInterface>hardware_interface/PositionJointInterface</hardwareInterface>
            <mechanicalReduction>1</mechanicalReduction>
        </actuator>
    </transmission>
    <!-- ros_control plugin -->
    <gazebo>
        <plugin filename="libgazebo_ros_control.so" name="gazebo_ros_control">
            <robotNamespace>/arm</robotNamespace>
            <robotSimType>gazebo_ros_control/DefaultRobotHWSim</robotSimType>
            <legacyModeNS>true</legacyModeNS>
        </plugin>
    </gazebo>
    <link name="tool_base_link">
        <inertial>
            <origin rpy="0 0 0" xyz="-0.000222405740733957 -0.000481035601624011 0.0689230138059816" />
            <mass value="0.116045321966342" />
            <inertia ixx="0.000164904816177466" ixy="2.02488130216797e-07" ixz="1.50577434202425e-06" iyy="0.000202510715131649" iyz="8.60308417309894e-06" izz="5.69762169244189e-05" />
        </inertial>
        <visual>
            <origin rpy="0 0 0" xyz="0 0 0" />
            <geometry>
                <mesh filename="package://conect_description/meshes/tool_base_link.STL" />
            </geometry>
            <material name="">
                <color rgba="1 1 1 1" />
            </material>
        </visual>
        <collision>
            <origin rpy="0 0 0" xyz="0 0 0" />
            <geometry>
                <mesh filename="package://conect_description/meshes/tool_base_link.STL" />
            </geometry>
        </collision>
    </link>
    <link name="tool_end_link">
        <inertial>
            <origin rpy="0 0 0" xyz="8.79459612690391E-05 -8.1632458962142E-05 -0.00099852848210466" />
            <mass value="8.00000000000001e-06" />
            <inertia ixx="5.33333333333336e-12" ixy="1.46216601377879e-27" ixz="1.41756869850412e-27" iyy="5.33333333333336e-12" iyz="-3.92889708655019e-28" izz="5.33333333333334e-12" />
        </inertial>
        <visual>
            <origin rpy="0 0 0" xyz="0 0 0" />
            <geometry>
                <mesh filename="package://conect_description/meshes/tool_end_link.STL" />
            </geometry>
            <material name="">
                <color rgba="1 1 1 1" />
            </material>
        </visual>
        <collision>
            <origin rpy="0 0 0" xyz="0 0 0" />
            <geometry>
                <mesh filename="package://conect_description/meshes/tool_end_link.STL" />
            </geometry>
        </collision>
    </link>
    <joint name="conect" type="fixed">
        <origin rpy="0 0 0" xyz="-0.00272826464929472 -0.00102217054955704 0.174" />
        <parent link="tool_base_link" />
        <child link="tool_end_link" />
        <axis xyz="0 0 0" />
    </joint>
    <joint name="link6_to_tool" type="fixed">
        <origin rpy="0 0 1.57" xyz="0 0 0.005" />
        <parent link="Link6" />
        <child link="tool_base_link" />
        <axis xyz="0 0 0" />
    </joint>
</robot>

